Workbook

Sheet Global Tracker
A1: THE DATA CARDS PLAYBOOK - ACTIVITY TRACKER • MMM YYYY • OSS | H1: The Data Cards Playbook ↗ by Google Research is licensed under a Creative Commons Attribution-ShareAlike 4.0 International License. You are free to share and adapt this work under the appropriate license terms ↗.
A2: Global Tracker
A3: Module 01 Ask | E3: Module 02 Inspect
A4: Track agents for are relevant or important for the agent information journey in the corresponding columns. Refer to this list when when you seek feedback or empirically validate your Data Card. | B4: Enter the lenses, themes, or sections in your Data Card or template. These should be easily converted into a short title for a section in your Data Card. | C4: Enter the specific prompts or questions in your Data Card or template. These are the specific information that your Data Card will convey about your Dataset. | D4: Use the dropdown to assign each question a scope type. Use this to track the level of detail required in the answer. | E4: Use the dropdown to assign each question an OFTEn category by intent: What is the intended category that this question should elicit a response for? This populates the OFTEn Calculator. | F4: Use the dropdown to indicate which will be the most trustworthy source on the answer. | G4: Use this RACI matrix to distribute workload and enable individuals in your organization or group to produce the ideal set of answers for your Data Card.
A5: Final Perspective | B5: Final Lenses | C5: Final Scopes | E5: Calculators | G5: Future Planning
A7: As a(n) [agent / perspective]... | B7: I want to know [lens]... | C7: so I ask [scopes]... | D7: Scope Type | E7: OFTEn Calculator | F7: 3 Buckets | G7: Responsible | H7: Accountable | I7: Consulted | J7: Informed
A8: Agents = use, evaluate, or determine how the dataset is used. | B8: Lens = A statement that describes what agents want to learn about the dataset from its Data Cards and documentation. | C8: Scopes = Questions framed around a lens that agents ask to get answers that help them make decisions. There are 3 kinds of scope questions: Telescopic: Questions about attributes commonly found across multiple datasets Periscopic: Questions about attributes specific to the producer’s dataset Microscopic: Questions about unobservable aspects of the dataset You can have more than one set of scopes for a lens. These becomes rows under each section in your Data Card. | E8: The 5 OFTEn categories are: 1. ORIGINS: The earliest part of the lifecycle, when decisions to create a dataset are made 2. FACTUALS: The actual data collection process and the outputs 3. TRANSFORMATIONS: Data is transformed through filtering, validating, parsing, formatting, and cleaning 4. EXPERIENCE: The dataset is benchmarked or deployed in practice (experimental, production, or research) 5. n = 1: Describes actual samples of data | F8: The 3 suggested buckets are: 1. Automatically Computed answer 2. Human written answer 3. Augmented/Combination answer Feel free to adapt the choices to fit your dataset. | G8: Individuals who perform a task in the creation of the dataset are responsible for producing answers relevant to that task. | H8: Individual who is ultimately responsible to deliver this task. Note that this includes yes/no and veto power. Only one A can be assigned to a task. | I8: Individuals consulted prior to reaching a final answer. They may offer their feedback, advice, or opinion, but can’t be held responsible, accountable, or liable for the outcome. They make no decisions in the answers. | J8: The individuals who must be informed during the process, after a decision has been made, or when an answer has been created.
B9: Lens 1 | C9: Telescopic Question
C11: Periscopic Question
C13: Microscopic Question
B15: Lens 2 | C15: Telescopic Question
C17: Periscopic Question
C19: Microscopic Question
B21: Lens 3 | C21: Telescopic Question
C23: Periscopic Question
C25: Microscopic Question
B27: Lens 4 | C27: Telescopic Question
C29: Periscopic Question
C31: Microscopic Question
B33: Lens 5 | C33: Telescopic Question
C35: Periscopic Question
C37: Microscopic Question
B39: Lens 6 | C39: Telescopic Question
C41: Periscopic Question
C43: Microscopic Question
B45: Lens 7 | C45: Telescopic Question
C47: Periscopic Question
C49: Microscopic Question
B51: Lens 8 | C51: Telescopic Question
C53: Periscopic Question
C55: Microscopic Question
B57: Lens 9 | C57: Telescopic Question
C59: Periscopic Question
C61: Microscopic Question
B63: Lens 10 | C63: Telescopic Question
C65: Periscopic Question
C67: Microscopic Question

Sheet Agents Brainstorm
A1: THE DATA CARDS PLAYBOOK • 01 ASK
A2: Agents Brainstorm Tracker
A3: INSTRUCTIONS: | B3: [1] Enter the list of Agents based on importance to your dataset and data card. | C3: [2] Use the dropdown to enter the Data Fluency level for each agent. This provides an estimate of how comfortable the audience will be with using, understanding, and acting on the Data Card. This populates calculators in future modules. | D3: [3] Use the dropdown to enter the Domain Expertise level for each agent. This provides an estimate of how much background knowledge the intended audience has to interpret the Data Card. This populates calculators in future modules. | E3: [4] Provide links or transcribe notes from the persona worksheets in the align on agents activity for reference. This will make them easy to locate in subsequent sessions.
A5: Importance | B5: Agent List | C5: Data Fluency | D5: Domain Expertise | E5: Notes about the agent
A6: Note: a Data Card will rarely work for everyone. That's ok. It should work 95% of the time for the top 3 agents, 75% of the time for the next 3, etc. | B6: Agents = use, evaluate, or determine how the dataset is used. | C6: Data Fluency is the familiarity and comfort that agents have with data, either in or outside of their domain of expertise. – No fluency: No data experience Limited fluency: Basic understanding of the concepts represented in the data (conversational) Average fluency: Ability to speak, write and engage in the data and its use cases (literate) High fluency: Competent in designing and developing projects around data or applying transformations onto the data Expert fluency: Strongly capable in understanding, manipulating and utilizing data across many domains | D6: Domain Knowledge implies knowledge and understanding of the essential aspects of a specific field of inquiry, in the domain of the dataset. _ No Expertise: Zero knowledge in domain Novice: Just starting to know about general issues or want to gain insight on some topic Intermediate: Can answer general questions and have some basic domain concepts Professional: Can answer and discuss domain specific topics well Expert: Highly informative and can timely answer critical questions
A7: 1 | B7: Agent 1 (eg. ML developer) | E7: Please replace this example with your results
A8: 2 | B8: Agent 2
A9: 3 | B9: Agent 3
A10: 4 | B10: Agent 4
A11: 5 | B11: Agent 5
A12: 6 | B12: Agent 6
A13: 7 | B13: Agent 7
A14: 8 | B14: Agent 8
A15: 9 | B15: Agent 9
A16: 10 | B16: Agent 10

Sheet Lens Brainstorm
A1: THE DATA CARDS PLAYBOOK • 01 ASK
A2: Lens Brainstorm Tracker
A3: INSTRUCTIONS:
A4: [1] Use the dropdown to select the OFTEn theme on the Lens card. | B4: [2] Using the dropdown, select the agent whose perspective is represented in the Lens Card | C4: [3] Enter the lens statement from the Lens Card. | D4: [4] Optionally, use the dropdown to give each Lens an importance rating to take to the next phase of the brainstorm.
A6: OFTEn Card used | B6: As a(n) [perspective] | C6: I want to know...[enter lens] | D6: Initial Importance Rating
A7: 5 OFTEn categories are: 1. ORIGINS: The earliest part of the lifecycle, when decisions to create a dataset are made 2. FACTUALS: The actual data collection process and the outputs 3. TRANSFORMATIONS: Data is transformed through filtering, validating, parsing, formatting, and cleaning 4. EXPERIENCE: The dataset is benchmarked or deployed in practice (experimental, production, or research) 5. n = 1: Describes actual samples of data OFTEn categories are fluid, so if unsure, select the most relevant for your lens, dataset, and Agent. | B7: An agent’s unique role that frames how they read Data Cards and other documentation. Agents = use, evaluate, or determine how the dataset is used. Stakeholders who use and evaluate datasets and their corresponding Data Cards. They can make decisions about the use of your dataset, which can be based solely on insights provided in dataset documentation. | C7: Lens= Statements that articulate what agents want to learn from a Data Card and other documentation. These should convey a single idea, and capture the unique perspective of the agent where applicable. You should be able to convert a Lens into a short title for a section in your Data Card. | D7: Choose one of 3 ratings: 1. Very important or essential 2. Somewhat important 3. Slightly importnatn This will help guide which Lenses you would like to breakdown Scopes for in the next brainstorm.
A8: Origins | B8: Agent 1 (eg. ML developer) | C8: The sources of the data | D8: Very important or essential

Sheet Scopes Brainstorm
A1: THE DATA CARDS PLAYBOOK • 01 ASK
A2: Scopes Brainstorm Tracker
A3: INSTRUCTIONS:
A4: [1] Enter the Lenses explored in the Scopes brainstorm. | B4: [2] Write the Scopes that were brainstormed from the associated Lens. You may have multiple sets of Scopes per Lens. Aim for between 1 and 3 sets of Scopes for each Lens. | C4: Use the dropdown to assign each question a scope type. | D4: [3] Once you have a list of well-written Scopes, decide which are most important to your Agents. It may be helpful to vote individually and then average the ratings to have an official group rating.
A6: As a(n) [perspective], I want to know...[enter lens] | B6: so I ask... [enter scopes] | C6: Type of Scope | D6: Initial Importance Rating
A7: Lens: A statement that describes what Agents want to learn about the dataset from its Data Cards and documentation. These account for the unique perspectives that Agents bring to the table. You should be able to convert a lens into a short title for a section in your Data Card. | B7: Input the Scopes below and indicate which type it is. Scopes = Questions framed around a lens that agents ask to get answers that help them make decisions. There are 3 kinds of scope questions: Telescopic: Questions about attributes commonly found across multiple datasets Periscopic: Questions about attributes specific to the producer’s dataset Microscopic: Questions about unobservable aspects of the dataset You can have more than one set of scopes for a lens. These becomes rows under each section in your Data Card. | D7: This will be your first gut call of which scopes are most important to the agent. This will be primarily used to guide which Scopes you might want to take forward to the template. Choose one of 3 ratings: 1. Very important or essential 2. Somewhat important 3. Slightly important This will help guide which Scopes to take forward to the Data Card template.
A8: (e.g. As an ML Developer, I want to how labels were created) | B8: [T]
B9: [P]
B10: [M]
B11: [T]
B12: [P]
B13: [M]
B14: [T]
B15: [P]
B16: [M]
B17: [T]
B18: [P]
B19: [M]
B20: [T]
... B43: [M]

Sheet Input Dimensions Worksheet
A1: THE DATA CARDS PLAYBOOK • 02 INSPECT
A2: Dimensions Worksheet
A3: INSTRUCTIONS: | B3: [1] Once the group has completed their Dimension Worksheets, capture the overall rating for each Dimension. Once the Data Card template is drafted, it's easy to see how a populated Data Card compares to the expectations set here. | C3: [2] Fill in the required Fluency for each of the Dimensions. This will populate the Fluency Calculators. | D3: [3] Fill in the required Domain Expertise for each of the Dimensions.
A5: Dimension | B5: Dimension Rating | C5: Required Data Fluency | D5: Required Domain Expertise
A6: Dimensions represent the different types of value judgements that agents make about a dataset from a Data Card. Use dimensions for directional insights into whether or not the Data Card helps Agents arrive at acceptable conclusions about the dataset. | B6: How well does the Data Card template support assessments for this Dimension? Use the dropdown to enter a rating for each Dimension. Pick from: - Outstanding - Solid - Average - Borderline - Poor | C6: What's the required Data Fluency needed to make an assessment for this Dimension? Use the dropdown to enter a rating for each Dimension. Reminder: Fluency is defined as the familiarity and comfort that Agents have with data, either in or outside of their domain of expertise. Pick from: - 1 (No Fluency) - 2 (Limited Fluency) - 3 (Average Fluency) - 4 (High Fluency) - 5 (Expert Fluency) | D6: If at all, what is the required Domain Expertise needed to make an assessment for this dimension? Use the dropdown to enter a rating for each Dimension. Reminder: Domain expertise implies knowledge and understanding of the essential aspects of a specific field of inquiry, in the domain of the dataset. Pick from: - 1 (No Expertise) - 2 (Novice) - 3 (Intermediate) - 4 (Professional) - 5 (Domain Expert)
A7: Accountability
A8: Impact & Consequences
A9: Quality
A10: Risk & Recommendations
A11: Use & Utility

Sheet Input Dimensions Ranking (for E
A1: THE DATA CARDS PLAYBOOK • 02 INSPECT
A2: Input: Dimensions Ranking (for Each Agent)
A3: How to use this sheet: | B3: [1] Rank each Dimension by their importance to your top 5 agents from the Priority Brainstorm. | C3: [2] These will populate the fluency calculator. Use the results of the fluency calculator to identify opportunities for improvement. | D3: NOTE – Unranked dimensions are shown below the fold.
A5: Rank | B5: ='Agents Brainstorm'!B7 -> Agent 1 (eg. ML developer) | C5: ='Agents Brainstorm'!B8 -> Agent 2 | D5: ='Agents Brainstorm'!B9 -> Agent 3 | E5: ='Agents Brainstorm'!B10 -> Agent 4 | F5: ='Agents Brainstorm'!B11 -> Agent 5
A6: 1
A7: 2
A8: 3
A9: 4
A10: 5
B12: Dimensions to be ranked: | C12: Dimensions to be ranked: | D12: Dimensions to be ranked: | E12: Dimensions to be ranked: | F12: Dimensions to be ranked:
B13: =IFERROR(__xludf.DUMMYFUNCTION("ifna(sort(filter('Input Dimensions Worksheet'!$A7:$A11,countif(B6:B10,'Input Dimensions Worksheet'!$A7:$A11)=0)))"),"Accountability") -> Accountability | C13: =IFERROR(__xludf.DUMMYFUNCTION("ifna(sort(filter('Input Dimensions Worksheet'!$A7:$A11,countif(C6:C10,'Input Dimensions Worksheet'!$A7:$A11)=0)))"),"Accountability") -> Accountability | D13: =IFERROR(__xludf.DUMMYFUNCTION("ifna(sort(filter('Input Dimensions Worksheet'!$A7:$A11,countif(D6:D10,'Input Dimensions Worksheet'!$A7:$A11)=0)))"),"Accountability") -> Accountability | E13: =IFERROR(__xludf.DUMMYFUNCTION("ifna(sort(filter('Input Dimensions Worksheet'!$A7:$A11,countif(E6:E10,'Input Dimensions Worksheet'!$A7:$A11)=0)))"),"Accountability") -> Accountability | F13: =IFERROR(__xludf.DUMMYFUNCTION("ifna(sort(filter('Input Dimensions Worksheet'!$A7:$A11,countif(F6:F10,'Input Dimensions Worksheet'!$A7:$A11)=0)))"),"Accountability") -> Accountability
B14: =IFERROR(__xludf.DUMMYFUNCTION("""COMPUTED_VALUE"""),"Impact & Consequences") -> Impact & Consequences | C14: =IFERROR(__xludf.DUMMYFUNCTION("""COMPUTED_VALUE"""),"Impact & Consequences") -> Impact & Consequences | D14: =IFERROR(__xludf.DUMMYFUNCTION("""COMPUTED_VALUE"""),"Impact & Consequences") -> Impact & Consequences | E14: =IFERROR(__xludf.DUMMYFUNCTION("""COMPUTED_VALUE"""),"Impact & Consequences") -> Impact & Consequences | F14: =IFERROR(__xludf.DUMMYFUNCTION("""COMPUTED_VALUE"""),"Impact & Consequences") -> Impact & Consequences
B15: =IFERROR(__xludf.DUMMYFUNCTION("""COMPUTED_VALUE"""),"Quality") -> Quality | C15: =IFERROR(__xludf.DUMMYFUNCTION("""COMPUTED_VALUE"""),"Quality") -> Quality | D15: =IFERROR(__xludf.DUMMYFUNCTION("""COMPUTED_VALUE"""),"Quality") -> Quality | E15: =IFERROR(__xludf.DUMMYFUNCTION("""COMPUTED_VALUE"""),"Quality") -> Quality | F15: =IFERROR(__xludf.DUMMYFUNCTION("""COMPUTED_VALUE"""),"Quality") -> Quality
B16: =IFERROR(__xludf.DUMMYFUNCTION("""COMPUTED_VALUE"""),"Risk & Recommendations") -> Risk & Recommendations | C16: =IFERROR(__xludf.DUMMYFUNCTION("""COMPUTED_VALUE"""),"Risk & Recommendations") -> Risk & Recommendations | D16: =IFERROR(__xludf.DUMMYFUNCTION("""COMPUTED_VALUE"""),"Risk & Recommendations") -> Risk & Recommendations | E16: =IFERROR(__xludf.DUMMYFUNCTION("""COMPUTED_VALUE"""),"Risk & Recommendations") -> Risk & Recommendations | F16: =IFERROR(__xludf.DUMMYFUNCTION("""COMPUTED_VALUE"""),"Risk & Recommendations") -> Risk & Recommendations
B17: =IFERROR(__xludf.DUMMYFUNCTION("""COMPUTED_VALUE"""),"Use & Utility") -> Use & Utility | C17: =IFERROR(__xludf.DUMMYFUNCTION("""COMPUTED_VALUE"""),"Use & Utility") -> Use & Utility | D17: =IFERROR(__xludf.DUMMYFUNCTION("""COMPUTED_VALUE"""),"Use & Utility") -> Use & Utility | E17: =IFERROR(__xludf.DUMMYFUNCTION("""COMPUTED_VALUE"""),"Use & Utility") -> Use & Utility | F17: =IFERROR(__xludf.DUMMYFUNCTION("""COMPUTED_VALUE"""),"Use & Utility") -> Use & Utility

Sheet Output Fluency Calculators
A1: THE DATA CARDS PLAYBOOK • 02 INSPECT
A2: Outputs: Fluency Calculator
A4: Fluency Calculator
A5: HOW TO INTERPRET: 1 is most fluenct, 5 is least fluent – 👎 = Difficult for agent to read 🤔 = Could be difficult 👍 = Looks safe _ NOTE: Calculator results are purely directional | C5: ='Agents Brainstorm'!B7 -> Agent 1 (eg. ML developer) | E5: ='Agents Brainstorm'!B8 -> Agent 2 | G5: ='Agents Brainstorm'!B9 -> Agent 3 | I5: ='Agents Brainstorm'!B10 -> Agent 4 | K5: ='Agents Brainstorm'!B11 -> Agent 5
B6: Available Fluency: | C6: =left('Agents Brainstorm'!C7, 1) | E6: =left('Agents Brainstorm'!C8, 1) | G6: =left('Agents Brainstorm'!C9, 1) | I6: =left('Agents Brainstorm'!C10, 1) | K6: =left('Agents Brainstorm'!C11, 1)
A7: Required Fluency: | B7: ='Input Dimensions Worksheet'!A7 -> Accountability | C7: =ifna(LEFT(VLOOKUP($B7,'Input Dimensions Worksheet'!$A$7:$C$11, 3), 1)) | D7: =if(C7>C$6, "👎", if(C7<C$6, "👍", "0")) -> 0 | E7: =ifna(LEFT(VLOOKUP($B7,'Input Dimensions Worksheet'!$A$7:$C$11, 3), 1)) | F7: =if(E7>E$6, "👎", if(E7<E$6, "👍", "🤔")) -> 🤔 | G7: =ifna(LEFT(VLOOKUP($B7,'Input Dimensions Worksheet'!$A$7:$C$11, 3), 1)) | H7: =if(G7>G$6, "👎", if(G7<G$6, "👍", "🤔")) -> 🤔 | I7: =ifna(LEFT(VLOOKUP($B7,'Input Dimensions Worksheet'!$A$7:$C$11, 3), 1)) | J7: =if(I7>I$6, "👎", if(I7<I$6, "👍", "🤔")) -> 🤔 | K7: =ifna(LEFT(VLOOKUP($B7,'Input Dimensions Worksheet'!$A$7:$C$11, 3), 1)) | L7: =if(K7>K$6, "👎", if(K7<K$6, "👍", "🤔")) -> 🤔
B8: ='Input Dimensions Worksheet'!A8 -> Impact & Consequences | C8: =ifna(LEFT(VLOOKUP($B8,'Input Dimensions Worksheet'!$A$7:$C$11, 3), 1)) | D8: =if(C8>C$6, "👎", if(C8<C$6, "👍", "0")) -> 0 | E8: =ifna(LEFT(VLOOKUP($B8,'Input Dimensions Worksheet'!$A$7:$C$11, 3), 1)) | F8: =if(E8>E$6, "👎", if(E8<E$6, "👍", "🤔")) -> 🤔 | G8: =ifna(LEFT(VLOOKUP($B8,'Input Dimensions Worksheet'!$A$7:$C$11, 3), 1)) | H8: =if(G8>G$6, "👎", if(G8<G$6, "👍", "🤔")) -> 🤔 | I8: =ifna(LEFT(VLOOKUP($B8,'Input Dimensions Worksheet'!$A$7:$C$11, 3), 1)) | J8: =if(I8>I$6, "👎", if(I8<I$6, "👍", "🤔")) -> 🤔 | K8: =ifna(LEFT(VLOOKUP($B8,'Input Dimensions Worksheet'!$A$7:$C$11, 3), 1)) | L8: =if(K8>K$6, "👎", if(K8<K$6, "👍", "🤔")) -> 🤔
B9: ='Input Dimensions Worksheet'!A9 -> Quality | C9: =ifna(LEFT(VLOOKUP($B9,'Input Dimensions Worksheet'!$A$7:$C$11, 3), 1)) | D9: =if(C9>C$6, "👎", if(C9<C$6, "👍", "0")) -> 0 | E9: =ifna(LEFT(VLOOKUP($B9,'Input Dimensions Worksheet'!$A$7:$C$11, 3), 1)) | F9: =if(E9>E$6, "👎", if(E9<E$6, "👍", "🤔")) -> 🤔 | G9: =ifna(LEFT(VLOOKUP($B9,'Input Dimensions Worksheet'!$A$7:$C$11, 3), 1)) | H9: =if(G9>G$6, "👎", if(G9<G$6, "👍", "🤔")) -> 🤔 | I9: =ifna(LEFT(VLOOKUP($B9,'Input Dimensions Worksheet'!$A$7:$C$11, 3), 1)) | J9: =if(I9>I$6, "👎", if(I9<I$6, "👍", "🤔")) -> 🤔 | K9: =ifna(LEFT(VLOOKUP($B9,'Input Dimensions Worksheet'!$A$7:$C$11, 3), 1)) | L9: =if(K9>K$6, "👎", if(K9<K$6, "👍", "🤔")) -> 🤔
B10: ='Input Dimensions Worksheet'!A10 -> Risk & Recommendations | C10: =ifna(LEFT(VLOOKUP($B10,'Input Dimensions Worksheet'!$A$7:$C$11, 3), 1)) | D10: =if(C10>C$6, "👎", if(C10<C$6, "👍", "0")) -> 0 | E10: =ifna(LEFT(VLOOKUP($B10,'Input Dimensions Worksheet'!$A$7:$C$11, 3), 1)) | F10: =if(E10>E$6, "👎", if(E10<E$6, "👍", "🤔")) -> 🤔 | G10: =ifna(LEFT(VLOOKUP($B10,'Input Dimensions Worksheet'!$A$7:$C$11, 3), 1)) | H10: =if(G10>G$6, "👎", if(G10<G$6, "👍", "🤔")) -> 🤔 | I10: =ifna(LEFT(VLOOKUP($B10,'Input Dimensions Worksheet'!$A$7:$C$11, 3), 1)) | J10: =if(I10>I$6, "👎", if(I10<I$6, "👍", "🤔")) -> 🤔 | K10: =ifna(LEFT(VLOOKUP($B10,'Input Dimensions Worksheet'!$A$7:$C$11, 3), 1)) | L10: =if(K10>K$6, "👎", if(K10<K$6, "👍", "🤔")) -> 🤔
B11: ='Input Dimensions Worksheet'!A11 -> Use & Utility | C11: =ifna(LEFT(VLOOKUP($B11,'Input Dimensions Worksheet'!$A$7:$C$11, 3), 1)) | D11: =if(C11>C$6, "👎", if(C11<C$6, "👍", "🤔")) -> 🤔 | E11: =ifna(LEFT(VLOOKUP($B11,'Input Dimensions Worksheet'!$A$7:$C$11, 3), 1)) | F11: =if(E11>E$6, "👎", if(E11<E$6, "👍", "🤔")) -> 🤔 | G11: =ifna(LEFT(VLOOKUP($B11,'Input Dimensions Worksheet'!$A$7:$C$11, 3), 1)) | H11: =if(G11>G$6, "👎", if(G11<G$6, "👍", "🤔")) -> 🤔 | I11: =ifna(LEFT(VLOOKUP($B11,'Input Dimensions Worksheet'!$A$7:$C$11, 3), 1)) | J11: =if(I11>I$6, "👎", if(I11<I$6, "👍", "🤔")) -> 🤔 | K11: =ifna(LEFT(VLOOKUP($B11,'Input Dimensions Worksheet'!$A$7:$C$11, 3), 1)) | L11: =if(K11>K$6, "👎", if(K11<K$6, "👍", "🤔")) -> 🤔
A13: Ranking Calculator
A14: HOW TO READ: 1 is most important, 5 is least important _ ❓Average: Average score. ❓Min: Highest ranking across all the agents. ❓Max: Lowest ranking across all the agents. _ NOTE: Calculator results are purely directional.
B15: Dimension | C15: Average Ranking | I15: Min | K15: Max
A16: Importance Ranking | B16: ='Input Dimensions Worksheet'!A7 -> Accountability | C16: {=IFNA(VLOOKUP(B16,{'Input Dimensions Ranking (for E'!$B$6:$B$10, 'Input Dimensions Ranking (for E'!$A$6:$A$10}, 2, False)+ VLOOKUP(B16,{'Input Dimensions Ranking (for E'!$C$6:$C$10, 'Input Dimensions Ranking (for E'!$A$6:$A$10}, 2, False)+ VLOOKUP(B16,{'Input Dimensions Ranking (for E'!$D$6:$D$10, 'Input Dimensions Ranking (for E'!$A$6:$A$10}, 2, False)+ VLOOKUP(B16,{'Input Dimensions Ranking (for E'!$E$6:$E$10, 'Input Dimensions Ranking (for E'!$A$6:$A$10}, 2, False)+ VLOOKUP(B16,{'Input Dimensions Ranking (for E'!$F$6:$F$10, 'Input Dimensions Ranking (for E'!$A$6:$A$10}, 2, False))/5} -> 0 | I16: {=ifna(min(VLOOKUP($B16,{'Input Dimensions Ranking (for E'!$B$6:$B$10, 'Input Dimensions Ranking (for E'!$A$6:$A$10}, 2, False), VLOOKUP($B16,{'Input Dimensions Ranking (for E'!$C$6:$C$10, 'Input Dimensions Ranking (for E'!$A$6:$A$10}, 2, False), VLOOKUP($B16,{'Input Dimensions Ranking (for E'!$D$6:$D$10, 'Input Dimensions Ranking (for E'!$A$6:$A$10}, 2, False), VLOOKUP($B16,{'Input Dimensions Ranking (for E'!$E$6:$E$10, 'Input Dimensions Ranking (for E'!$A$6:$A$10}, 2, False), VLOOKUP($B16,{'Input Dimensions Ranking (for E'!$F$6:$F$10, 'Input Dimensions Ranking (for E'!$A$6:$A$10}, 2, False)),1)} -> 1 | K16: {=ifna(MAX(VLOOKUP($B16,{'Input Dimensions Ranking (for E'!$B$6:$B$10, 'Input Dimensions Ranking (for E'!$A$6:$A$10}, 2, False), VLOOKUP($B16,{'Input Dimensions Ranking (for E'!$C$6:$C$10, 'Input Dimensions Ranking (for E'!$A$6:$A$10}, 2, False), VLOOKUP($B16,{'Input Dimensions Ranking (for E'!$D$6:$D$10, 'Input Dimensions Ranking (for E'!$A$6:$A$10}, 2, False), VLOOKUP($B16,{'Input Dimensions Ranking (for E'!$E$6:$E$10, 'Input Dimensions Ranking (for E'!$A$6:$A$10}, 2, False), VLOOKUP($B16,{'Input Dimensions Ranking (for E'!$F$6:$F$10, 'Input Dimensions Ranking (for E'!$A$6:$A$10}, 2, False)),1)} -> 1
B17: ='Input Dimensions Worksheet'!A8 -> Impact & Consequences | C17: {=IFNA(VLOOKUP(B17,{'Input Dimensions Ranking (for E'!$B$6:$B$10, 'Input Dimensions Ranking (for E'!$A$6:$A$10}, 2, False)+ VLOOKUP(B17,{'Input Dimensions Ranking (for E'!$C$6:$C$10, 'Input Dimensions Ranking (for E'!$A$6:$A$10}, 2, False)+ VLOOKUP(B17,{'Input Dimensions Ranking (for E'!$D$6:$D$10, 'Input Dimensions Ranking (for E'!$A$6:$A$10}, 2, False)+ VLOOKUP(B17,{'Input Dimensions Ranking (for E'!$E$6:$E$10, 'Input Dimensions Ranking (for E'!$A$6:$A$10}, 2, False)+ VLOOKUP(B17,{'Input Dimensions Ranking (for E'!$F$6:$F$10, 'Input Dimensions Ranking (for E'!$A$6:$A$10}, 2, False))/5} -> 0 | I17: {=ifna(min(VLOOKUP($B17,{'Input Dimensions Ranking (for E'!$B$6:$B$10, 'Input Dimensions Ranking (for E'!$A$6:$A$10}, 2, False), VLOOKUP($B17,{'Input Dimensions Ranking (for E'!$C$6:$C$10, 'Input Dimensions Ranking (for E'!$A$6:$A$10}, 2, False), VLOOKUP($B17,{'Input Dimensions Ranking (for E'!$D$6:$D$10, 'Input Dimensions Ranking (for E'!$A$6:$A$10}, 2, False), VLOOKUP($B17,{'Input Dimensions Ranking (for E'!$E$6:$E$10, 'Input Dimensions Ranking (for E'!$A$6:$A$10}, 2, False), VLOOKUP($B17,{'Input Dimensions Ranking (for E'!$F$6:$F$10, 'Input Dimensions Ranking (for E'!$A$6:$A$10}, 2, False)),1)} -> 1 | K17: {=ifna(MAX(VLOOKUP($B17,{'Input Dimensions Ranking (for E'!$B$6:$B$10, 'Input Dimensions Ranking (for E'!$A$6:$A$10}, 2, False), VLOOKUP($B17,{'Input Dimensions Ranking (for E'!$C$6:$C$10, 'Input Dimensions Ranking (for E'!$A$6:$A$10}, 2, False), VLOOKUP($B17,{'Input Dimensions Ranking (for E'!$D$6:$D$10, 'Input Dimensions Ranking (for E'!$A$6:$A$10}, 2, False), VLOOKUP($B17,{'Input Dimensions Ranking (for E'!$E$6:$E$10, 'Input Dimensions Ranking (for E'!$A$6:$A$10}, 2, False), VLOOKUP($B17,{'Input Dimensions Ranking (for E'!$F$6:$F$10, 'Input Dimensions Ranking (for E'!$A$6:$A$10}, 2, False)),1)} -> 1
B18: ='Input Dimensions Worksheet'!A9 -> Quality | C18: {=IFNA(VLOOKUP(B18,{'Input Dimensions Ranking (for E'!$B$6:$B$10, 'Input Dimensions Ranking (for E'!$A$6:$A$10}, 2, False)+ VLOOKUP(B18,{'Input Dimensions Ranking (for E'!$C$6:$C$10, 'Input Dimensions Ranking (for E'!$A$6:$A$10}, 2, False)+ VLOOKUP(B18,{'Input Dimensions Ranking (for E'!$D$6:$D$10, 'Input Dimensions Ranking (for E'!$A$6:$A$10}, 2, False)+ VLOOKUP(B18,{'Input Dimensions Ranking (for E'!$E$6:$E$10, 'Input Dimensions Ranking (for E'!$A$6:$A$10}, 2, False)+ VLOOKUP(B18,{'Input Dimensions Ranking (for E'!$F$6:$F$10, 'Input Dimensions Ranking (for E'!$A$6:$A$10}, 2, False))/5} -> 0 | I18: {=ifna(min(VLOOKUP($B18,{'Input Dimensions Ranking (for E'!$B$6:$B$10, 'Input Dimensions Ranking (for E'!$A$6:$A$10}, 2, False), VLOOKUP($B18,{'Input Dimensions Ranking (for E'!$C$6:$C$10, 'Input Dimensions Ranking (for E'!$A$6:$A$10}, 2, False), VLOOKUP($B18,{'Input Dimensions Ranking (for E'!$D$6:$D$10, 'Input Dimensions Ranking (for E'!$A$6:$A$10}, 2, False), VLOOKUP($B18,{'Input Dimensions Ranking (for E'!$E$6:$E$10, 'Input Dimensions Ranking (for E'!$A$6:$A$10}, 2, False), VLOOKUP($B18,{'Input Dimensions Ranking (for E'!$F$6:$F$10, 'Input Dimensions Ranking (for E'!$A$6:$A$10}, 2, False)),1)} -> 1 | K18: {=ifna(MAX(VLOOKUP($B18,{'Input Dimensions Ranking (for E'!$B$6:$B$10, 'Input Dimensions Ranking (for E'!$A$6:$A$10}, 2, False), VLOOKUP($B18,{'Input Dimensions Ranking (for E'!$C$6:$C$10, 'Input Dimensions Ranking (for E'!$A$6:$A$10}, 2, False), VLOOKUP($B18,{'Input Dimensions Ranking (for E'!$D$6:$D$10, 'Input Dimensions Ranking (for E'!$A$6:$A$10}, 2, False), VLOOKUP($B18,{'Input Dimensions Ranking (for E'!$E$6:$E$10, 'Input Dimensions Ranking (for E'!$A$6:$A$10}, 2, False), VLOOKUP($B18,{'Input Dimensions Ranking (for E'!$F$6:$F$10, 'Input Dimensions Ranking (for E'!$A$6:$A$10}, 2, False)),1)} -> 1
B19: ='Input Dimensions Worksheet'!A10 -> Risk & Recommendations | C19: {=IFNA(VLOOKUP(B19,{'Input Dimensions Ranking (for E'!$B$6:$B$10, 'Input Dimensions Ranking (for E'!$A$6:$A$10}, 2, False)+ VLOOKUP(B19,{'Input Dimensions Ranking (for E'!$C$6:$C$10, 'Input Dimensions Ranking (for E'!$A$6:$A$10}, 2, False)+ VLOOKUP(B19,{'Input Dimensions Ranking (for E'!$D$6:$D$10, 'Input Dimensions Ranking (for E'!$A$6:$A$10}, 2, False)+ VLOOKUP(B19,{'Input Dimensions Ranking (for E'!$E$6:$E$10, 'Input Dimensions Ranking (for E'!$A$6:$A$10}, 2, False)+ VLOOKUP(B19,{'Input Dimensions Ranking (for E'!$F$6:$F$10, 'Input Dimensions Ranking (for E'!$A$6:$A$10}, 2, False))/5} -> 0 | I19: {=ifna(min(VLOOKUP($B19,{'Input Dimensions Ranking (for E'!$B$6:$B$10, 'Input Dimensions Ranking (for E'!$A$6:$A$10}, 2, False), VLOOKUP($B19,{'Input Dimensions Ranking (for E'!$C$6:$C$10, 'Input Dimensions Ranking (for E'!$A$6:$A$10}, 2, False), VLOOKUP($B19,{'Input Dimensions Ranking (for E'!$D$6:$D$10, 'Input Dimensions Ranking (for E'!$A$6:$A$10}, 2, False), VLOOKUP($B19,{'Input Dimensions Ranking (for E'!$E$6:$E$10, 'Input Dimensions Ranking (for E'!$A$6:$A$10}, 2, False), VLOOKUP($B19,{'Input Dimensions Ranking (for E'!$F$6:$F$10, 'Input Dimensions Ranking (for E'!$A$6:$A$10}, 2, False)),1)} -> 1 | K19: {=ifna(MAX(VLOOKUP($B19,{'Input Dimensions Ranking (for E'!$B$6:$B$10, 'Input Dimensions Ranking (for E'!$A$6:$A$10}, 2, False), VLOOKUP($B19,{'Input Dimensions Ranking (for E'!$C$6:$C$10, 'Input Dimensions Ranking (for E'!$A$6:$A$10}, 2, False), VLOOKUP($B19,{'Input Dimensions Ranking (for E'!$D$6:$D$10, 'Input Dimensions Ranking (for E'!$A$6:$A$10}, 2, False), VLOOKUP($B19,{'Input Dimensions Ranking (for E'!$E$6:$E$10, 'Input Dimensions Ranking (for E'!$A$6:$A$10}, 2, False), VLOOKUP($B19,{'Input Dimensions Ranking (for E'!$F$6:$F$10, 'Input Dimensions Ranking (for E'!$A$6:$A$10}, 2, False)),1)} -> 1
B20: ='Input Dimensions Worksheet'!A11 -> Use & Utility | C20: {=IFNA(VLOOKUP(B20,{'Input Dimensions Ranking (for E'!$B$6:$B$10, 'Input Dimensions Ranking (for E'!$A$6:$A$10}, 2, False)+ VLOOKUP(B20,{'Input Dimensions Ranking (for E'!$C$6:$C$10, 'Input Dimensions Ranking (for E'!$A$6:$A$10}, 2, False)+ VLOOKUP(B20,{'Input Dimensions Ranking (for E'!$D$6:$D$10, 'Input Dimensions Ranking (for E'!$A$6:$A$10}, 2, False)+ VLOOKUP(B20,{'Input Dimensions Ranking (for E'!$E$6:$E$10, 'Input Dimensions Ranking (for E'!$A$6:$A$10}, 2, False)+ VLOOKUP(B20,{'Input Dimensions Ranking (for E'!$F$6:$F$10, 'Input Dimensions Ranking (for E'!$A$6:$A$10}, 2, False))/5} -> 0 | I20: {=ifna(min(VLOOKUP($B20,{'Input Dimensions Ranking (for E'!$B$6:$B$10, 'Input Dimensions Ranking (for E'!$A$6:$A$10}, 2, False), VLOOKUP($B20,{'Input Dimensions Ranking (for E'!$C$6:$C$10, 'Input Dimensions Ranking (for E'!$A$6:$A$10}, 2, False), VLOOKUP($B20,{'Input Dimensions Ranking (for E'!$D$6:$D$10, 'Input Dimensions Ranking (for E'!$A$6:$A$10}, 2, False), VLOOKUP($B20,{'Input Dimensions Ranking (for E'!$E$6:$E$10, 'Input Dimensions Ranking (for E'!$A$6:$A$10}, 2, False), VLOOKUP($B20,{'Input Dimensions Ranking (for E'!$F$6:$F$10, 'Input Dimensions Ranking (for E'!$A$6:$A$10}, 2, False)),1)} -> 1 | K20: {=ifna(MAX(VLOOKUP($B20,{'Input Dimensions Ranking (for E'!$B$6:$B$10, 'Input Dimensions Ranking (for E'!$A$6:$A$10}, 2, False), VLOOKUP($B20,{'Input Dimensions Ranking (for E'!$C$6:$C$10, 'Input Dimensions Ranking (for E'!$A$6:$A$10}, 2, False), VLOOKUP($B20,{'Input Dimensions Ranking (for E'!$D$6:$D$10, 'Input Dimensions Ranking (for E'!$A$6:$A$10}, 2, False), VLOOKUP($B20,{'Input Dimensions Ranking (for E'!$E$6:$E$10, 'Input Dimensions Ranking (for E'!$A$6:$A$10}, 2, False), VLOOKUP($B20,{'Input Dimensions Ranking (for E'!$F$6:$F$10, 'Input Dimensions Ranking (for E'!$A$6:$A$10}, 2, False)),1)} -> 1

Sheet Output OFTEn Calculators
A1: THE DATA CARDS PLAYBOOK • 02 INSPECT
A2: Outputs: OFTEn Calculator
A5: OFTEn Calculator
B7: Count
A8: Summary | B8: =countif('Global Tracker'!E:E, A8) -> 0
A9: Origins | B9: =countif('Global Tracker'!E:E, A9) -> 0
A10: Factuals | B10: =countif('Global Tracker'!E:E, A10) -> 0
A11: Transformations | B11: =countif('Global Tracker'!E:E, A11) -> 0
A12: Experience | B12: =countif('Global Tracker'!E:E, A12) -> 0
A13: n=1 | B13: =countif('Global Tracker'!E:E, A13) -> 0
A14: Others | B14: =countif('Global Tracker'!E:E, A14) -> 0
A15: N/A | B15: =countif('Global Tracker'!E:E, A15) -> 0

Sheet Deprecated Example DMC Tracker 
A1: DMC Playbook | D1: OFTEn coverage | E1: check | F1: balance | G1: agent | H1: importance | J1: AIP risk assessment framework
A2: Official Tracker | D2: Calculator 1 | E2: Calculator 2 | J2: Calculator 3 | M2: Accountability | R2: Chapter 3
A4: As a [enter Perspective Type]... | B4: I want to know... | C4: so I ask... | D4: OFTEn | E4: Theme | F4: Helpfulness | G4: Agent | H4: Helpfulness | I4: Health Score | J4: Risk Type | K4: Risk Level | L4: Detailed Findings | M4: Plan | N4: Responsbile | O4: Accountable | P4: Consulted | Q4: Informed | R4: Status | S4: PRDs | T4: Latest Design | U4: Buganizer Hotlists | V4: OKR links | W4: Owners
A5: 01 Ask / Lenses & Scopes | B5: 01 Ask / Lenses & Scopes | C5: 01 Ask / Lenses & Scopes | D5: 02 Inspect / Gut Check | E5: 02 Inspect / Gut Check | F5: 02 Inspect / Gut Check | G5: 02 Inspect / Gut Check | H5: 02 Inspect / Gut Check | J5: 02 Inspect / Gut Check | K5: 02 Inspect / Gut Check | L5: 02 Inspect / Gut Check | M5: 02 Inspect / Future Plans | N5: 02 Inspect / Future Plans | O5: 02 Inspect / Future Plans | P5: 02 Inspect / Future Plans | Q5: 02 Inspect / Future Plans
A6: Perspective: The specific role of the agent engaging with the data or model card | B6: Lens: What the perspective ultimately wants to accomplish to fulfill a higher level need. This is not time bound and can happen across products. Clustered + Processed --> Brainstorm | C6: Scopes: A specific step to completing the Goal. Often times they are shorter in duration and have a clear end state. Clustered + Processed --> Brainstorm | D6: OFTEn - Assign an often category to each scope | E6: OFTEn - Assign an often category to each scope | F6: How helpful is this scope to the agents to meet their Goals. This helps your team focus on which scopes are the most important. | G6: This scope is directed towards | I6: How easy or difficult it is for users to complete the Tasks of the Journey. Use issues identified in your Inspections and other sources (e.g. Bugs) to inform the Health Score. | J6: They type of risk associated with this scope | K6: The severity of this risk, weighed against it's likelihood. | L6: Link to reports and Scorecards that provide more detail of the Risk, Health Score and what to improve if it is At Risk or Unhealthy. | M6: Come together as a team to decide what the most trustworthy source on answer will be. We gave you some suggestions, but feel free to adapt. | R6: Routinely update progress on the Plan and link updates ine next few columns (PRDs, Designs, etc.) Best to make this part of your OKR process. | S6: Link to PRDs that are aimed at improving the CUJ. | T6: Links to the latest exprience (walk through, mocks, prototypes, etc.). | U6: Links to any Bugs that have been filed. | V6: Link to the OKRs that articulate what you trying to solve | W6: Ldaps of the XFN Team that is responsible for CUJ. All CUJs should have owners regardless of Health Status.
A7: Data Scientist | B7: About the nature of the dataset | C7: What is the structure of the table? | D7: Facts | E7: Actionability / Demonstration | F7: Moderately helpful | I7: Healthy | J7: Tech + Use | K7: Healthy | M7: Human only answer
A8: Epidemiologist
A9: ML Researcher | C9: How many features are in the dataset? | D9: Facts | E9: Actionability / Demonstration | F9: Slightly helpful | K9: Healthy | M9: Automatically calculated answer
A10: Public Health Official
A11: Archivist | C11: Are there any correlations in the features? | D11: Transformations | E11: Considerations | F11: Extremely helpful | K11: Medium Risk | M11: Combination answer
A13: Epidemiologist | B13: About the funding of the dataset | C13: How was the dataset funded? | D13: Origins | E13: Ownership | F13: Moderately helpful | J13: Tech + Use | K13: Healthy
A14: Public Health Official
A15: Archivist | C15: Who funded it? | D15: Origins | E15: Ownership | F15: Very helpful | J15: Tech + Use | K15: Low Risk
C17: Were there any conditions to the funding? | D17: Origins | E17: Ownership | F17: Extremely helpful | J17: System Level | K17: High Risk
A19: Data Scientist | B19: If this dataset represents groups of interest | C19: Is this human data? | D19: Facts | E19: Source | F19: Slightly helpful
A20: Epidemiologist
A21: ML Researcher | C21: Which groups are represented in the dataset? | D21: Facts | E21: Representation | F21: Very helpful
C23: Why were these specific groups represented? | D23: Origins | E23: Rationale | F23: Very helpful
B25: Lens 4 | C25: Telescopic Question | D25: n=1 | E25: Representation
C27: Periscopic Question | D27: Other | E27: Use by Self
C29: Microscopic Question | D29: N/A | E29: Use by Self
B31: Lens 5 | C31: Telescopic Question | D31: Other | E31: Versions | F31: Slightly helpful
C33: Periscopic Question | D33: n=1 | E33: Procedures
C35: Microscopic Question | D35: n=1 | E35: Validity
B37: Lens 6 | C37: Telescopic Question | D37: Experience | E37: Representation
C39: Periscopic Question | D39: Experience | E39: Validity
C41: Microscopic Question | D41: Experience | E41: None of the above
B43: Lens 7 | C43: Telescopic Question
C45: Periscopic Question
C47: Microscopic Question
B49: Lens 8 | C49: Telescopic Question
C51: Periscopic Question
C53: Microscopic Question
B55: Lens 9 | C55: Telescopic Question
C57: Periscopic Question
C59: Microscopic Question
B61: Lens 10 | C61: Telescopic Question
C63: Periscopic Question
C65: Microscopic Question

Sheet Deprecated Test bed
A1: DMC Playbook | D1: OFTEn coverage
A2: Calculators Test Bed | D2: Calculator 1
A4: As a [enter Perspective Type]... | B4: I want to know... | C4: so I ask... | D4: OFTEn
A5: 01 Ask / Lenses & Scopes | B5: 01 Ask / Lenses & Scopes | C5: 01 Ask / Lenses & Scopes | D5: 02 Inspect / Gut Check
A6: Perspective: The specific role of the agent engaging with the data or model card | B6: Lens: What the perspective ultimately wants to accomplish to fulfill a higher level need. This is not time bound and can happen across products. | C6: Scopes: A specific step to completing the Goal. Often times they are shorter in duration and have a clear end state. | D6: Origins | E6: Facts | F6: Transformations | G6: Experience | H6: N=1
B7: Clustered + Processed --> Brainstorm | D7: description + Instructions
A8: Data Scientist | B8: About the nature of the dataset | C8: What is the structure of the table? | D8: Tight Coupling | E8: Tight Coupling | F8: Primary | I8: =if(countif(D8:H8,"Primary")=1, "Done", if(countif(D8:H8,"Primary")>1, "Select ONE primary field", "Select primary field")) -> Done
A9: Epidemiologist | B9: About the nature of the dataset | C9: What is the structure of the table? | D9: Medium Coupling | E9: Medium Coupling | F9: Primary | I9: =if(countif(D9:H9,"Primary")=1, "Done", if(countif(D9:H9,"Primary")>1, "Select ONE primary field", "Select primary field")) -> Done
A10: ML Researcher | B10: About the nature of the dataset | C10: How many features are in the dataset? | D10: Loose Coupling | E10: Loose Coupling | F10: Primary | I10: =if(countif(D10:H10,"Primary")=1, "Done", if(countif(D10:H10,"Primary")>1, "Select ONE primary field", "Select primary field")) -> Done
A11: Public Health Official | B11: About the nature of the dataset | C11: How many features are in the dataset? | D11: N/A | E11: N/A | F11: Primary | I11: =if(countif(D11:H11,"Primary")=1, "Done", if(countif(D11:H11,"Primary")>1, "Select ONE primary field", "Select primary field")) -> Done
A12: Archivist | B12: About the nature of the dataset | C12: Are there any correlations in the features? | D12: Tight Coupling | E12: Tight Coupling | F12: Primary | I12: =if(countif(D12:H12,"Primary")=1, "Done", if(countif(D12:H12,"Primary")>1, "Select ONE primary field", "Select primary field")) -> Done
A13: Epidemiologist | B13: About the funding of the dataset | C13: How was the dataset funded? | D13: Medium Coupling | E13: Medium Coupling | F13: Primary | I13: =if(countif(D13:H13,"Primary")=1, "Done", if(countif(D13:H13,"Primary")>1, "Select ONE primary field", "Select primary field")) -> Done
A14: Public Health Official | B14: About the funding of the dataset | C14: How was the dataset funded? | D14: Loose Coupling | E14: Loose Coupling | F14: Primary | I14: =if(countif(D14:H14,"Primary")=1, "Done", if(countif(D14:H14,"Primary")>1, "Select ONE primary field", "Select primary field")) -> Done
A15: Archivist | B15: About the funding of the dataset | C15: Who funded it? | D15: N/A | E15: N/A | F15: Primary | I15: =if(countif(D15:H15,"Primary")=1, "Done", if(countif(D15:H15,"Primary")>1, "Select ONE primary field", "Select primary field")) -> Done
B16: About the funding of the dataset | C16: Who funded it? | D16: Tight Coupling | E16: Tight Coupling | F16: Primary | I16: =if(countif(D16:H16,"Primary")=1, "Done", if(countif(D16:H16,"Primary")>1, "Select ONE primary field", "Select primary field")) -> Done
B17: About the funding of the dataset | C17: Were there any conditions to the funding? | D17: Medium Coupling | E17: Medium Coupling | F17: Primary | I17: =if(countif(D17:H17,"Primary")=1, "Done", if(countif(D17:H17,"Primary")>1, "Select ONE primary field", "Select primary field")) -> Done
B18: About the funding of the dataset | C18: Were there any conditions to the funding? | D18: Loose Coupling | E18: Loose Coupling | F18: Primary | I18: =if(countif(D18:H18,"Primary")=1, "Done", if(countif(D18:H18,"Primary")>1, "Select ONE primary field", "Select primary field")) -> Done
A19: Data Scientist | B19: If this dataset represents groups of interest | C19: Is this human data? | D19: N/A | E19: N/A | F19: Primary | I19: =if(countif(D19:H19,"Primary")=1, "Done", if(countif(D19:H19,"Primary")>1, "Select ONE primary field", "Select primary field")) -> Done
A20: Epidemiologist | B20: If this dataset represents groups of interest | C20: Is this human data? | D20: Tight Coupling | E20: Tight Coupling | F20: Primary | G20: Tight Coupling | I20: =if(countif(D20:H20,"Primary")=1, "Done", if(countif(D20:H20,"Primary")>1, "Select ONE primary field", "Select primary field")) -> Done
A21: ML Researcher | B21: If this dataset represents groups of interest | C21: Which groups are represented in the dataset? | D21: Medium Coupling | E21: Medium Coupling | F21: Primary | G21: Medium Coupling | I21: =if(countif(D21:H21,"Primary")=1, "Done", if(countif(D21:H21,"Primary")>1, "Select ONE primary field", "Select primary field")) -> Done
B22: If this dataset represents groups of interest | D22: Loose Coupling | E22: Loose Coupling | F22: Primary | G22: Loose Coupling | I22: =if(countif(D22:H22,"Primary")=1, "Done", if(countif(D22:H22,"Primary")>1, "Select ONE primary field", "Select primary field")) -> Done
B23: If this dataset represents groups of interest | C23: Why were these specific groups represented? | D23: N/A | E23: N/A | F23: Primary | G23: N/A | I23: =if(countif(D23:H23,"Primary")=1, "Done", if(countif(D23:H23,"Primary")>1, "Select ONE primary field", "Select primary field")) -> Done
B24: If this dataset represents groups of interest | D24: Tight Coupling | E24: Tight Coupling | F24: Primary | G24: Tight Coupling | I24: =if(countif(D24:H24,"Primary")=1, "Done", if(countif(D24:H24,"Primary")>1, "Select ONE primary field", "Select primary field")) -> Done
B25: Lens 4 | C25: Telescopic Question | D25: Medium Coupling | E25: Medium Coupling | F25: Primary | G25: Medium Coupling | I25: =if(countif(D25:H25,"Primary")=1, "Done", if(countif(D25:H25,"Primary")>1, "Select ONE primary field", "Select primary field")) -> Done
B26: Lens 4 | C26: Telescopic Question | D26: Loose Coupling | E26: Loose Coupling | F26: Primary | G26: Loose Coupling | I26: =if(countif(D26:H26,"Primary")=1, "Done", if(countif(D26:H26,"Primary")>1, "Select ONE primary field", "Select primary field")) -> Done
B27: Lens 4 | C27: Periscopic Question | D27: N/A | E27: N/A | F27: Primary | G27: N/A | I27: =if(countif(D27:H27,"Primary")=1, "Done", if(countif(D27:H27,"Primary")>1, "Select ONE primary field", "Select primary field")) -> Done
B28: Lens 4 | C28: Periscopic Question | D28: Tight Coupling | E28: Tight Coupling | F28: Primary | G28: Tight Coupling | I28: =if(countif(D28:H28,"Primary")=1, "Done", if(countif(D28:H28,"Primary")>1, "Select ONE primary field", "Select primary field")) -> Done
B29: Lens 4 | C29: Microscopic Question | D29: Medium Coupling | E29: Medium Coupling | F29: Primary | G29: Medium Coupling | I29: =if(countif(D29:H29,"Primary")=1, "Done", if(countif(D29:H29,"Primary")>1, "Select ONE primary field", "Select primary field")) -> Done
B30: Lens 4 | C30: Microscopic Question | D30: Loose Coupling | E30: Loose Coupling | F30: Primary | G30: Loose Coupling | I30: =if(countif(D30:H30,"Primary")=1, "Done", if(countif(D30:H30,"Primary")>1, "Select ONE primary field", "Select primary field")) -> Done
B31: Lens 5 | C31: Telescopic Question | D31: N/A | E31: N/A | F31: Primary | G31: N/A | I31: =if(countif(D31:H31,"Primary")=1, "Done", if(countif(D31:H31,"Primary")>1, "Select ONE primary field", "Select primary field")) -> Done
B32: Lens 5 | C32: Telescopic Question | D32: Tight Coupling | E32: Tight Coupling | F32: Primary | H32: Tight Coupling | I32: =if(countif(D32:H32,"Primary")=1, "Done", if(countif(D32:H32,"Primary")>1, "Select ONE primary field", "Select primary field")) -> Done
B33: Lens 5 | C33: Periscopic Question | D33: Medium Coupling | E33: Medium Coupling | F33: Primary | H33: Medium Coupling | I33: =if(countif(D33:H33,"Primary")=1, "Done", if(countif(D33:H33,"Primary")>1, "Select ONE primary field", "Select primary field")) -> Done
B34: Lens 5 | C34: Periscopic Question | D34: Loose Coupling | E34: Loose Coupling | F34: Primary | H34: Loose Coupling | I34: =if(countif(D34:H34,"Primary")=1, "Done", if(countif(D34:H34,"Primary")>1, "Select ONE primary field", "Select primary field")) -> Done
B35: Lens 5 | C35: Microscopic Question | D35: N/A | E35: N/A | F35: Primary | H35: N/A | I35: =if(countif(D35:H35,"Primary")=1, "Done", if(countif(D35:H35,"Primary")>1, "Select ONE primary field", "Select primary field")) -> Done
B36: Lens 5 | C36: Microscopic Question | D36: Tight Coupling | E36: Tight Coupling | F36: Primary | H36: Tight Coupling | I36: =if(countif(D36:H36,"Primary")=1, "Done", if(countif(D36:H36,"Primary")>1, "Select ONE primary field", "Select primary field")) -> Done
B37: Lens 6 | C37: Telescopic Question | D37: Medium Coupling | E37: Medium Coupling | F37: Primary | H37: Medium Coupling | I37: =if(countif(D37:H37,"Primary")=1, "Done", if(countif(D37:H37,"Primary")>1, "Select ONE primary field", "Select primary field")) -> Done
B38: Lens 6 | C38: Telescopic Question | D38: Loose Coupling | E38: Loose Coupling | F38: Primary | H38: Loose Coupling | I38: =if(countif(D38:H38,"Primary")=1, "Done", if(countif(D38:H38,"Primary")>1, "Select ONE primary field", "Select primary field")) -> Done
B39: Lens 6 | C39: Periscopic Question | D39: N/A | E39: Primary | F39: Primary | H39: N/A | I39: =if(countif(D39:H39,"Primary")=1, "Done", if(countif(D39:H39,"Primary")>1, "Select ONE primary field", "Select primary field")) -> Select ONE primary field
B40: Lens 6 | C40: Periscopic Question | D40: Primary | E40: Primary | H40: Tight Coupling | I40: =if(countif(D40:H40,"Primary")=1, "Done", if(countif(D40:H40,"Primary")>1, "Select ONE primary field", "Select primary field")) -> Select ONE primary field
B41: Lens 6 | C41: Microscopic Question | D41: Primary | E41: Primary | H41: Medium Coupling | I41: =if(countif(D41:H41,"Primary")=1, "Done", if(countif(D41:H41,"Primary")>1, "Select ONE primary field", "Select primary field")) -> Select ONE primary field
...

Sheet Deprecated Test bed Visualizati
C2: Primary | D2: Tight Coupling | E2: Medium Coupling | F2: Loose Coupling | G2: N/A
B3: Origins: description + Instructions
B4: Facts: description + Instructions
B5: Transformations: description + Instructions
B6: Experience: description + Instructions
B7: N=1: description + Instructions
D10: Origins vs. Facts
D11: Origins
D12: Primary | E12: Tight Coupling | F12: Medium Coupling | G12: Loose Coupling | H12: N/A
B13: Fact | C13: Primary
C14: Tight Coupling
C15: Medium Coupling
C16: Loose Coupling
C17: N/A
J23: Small multiples visualization (Pairwise count breakdown) | L23: Coupling
A24: Coupling Matrix (Pairwise count) | C24: Coupling | L24: Origins | P24: Facts | T24: Transformations | X24: Experience | AB24: N=1
C25: Origins | D25: Facts | E25: Transformations | F25: Experience | G25: N=1 | L25: T | M25: M | N25: L | O25: N/A | P25: T | Q25: M | R25: L | S25: N/A | T25: T | U25: M | V25: L | W25: N/A | X25: T | Y25: M | Z25: L | AA25: N/A | AB25: T | AC25: M | AD25: L | AE25: N/A
A26: Primary | B26: Origins | D26: coupling count | E26: coupling count | F26: coupling count | G26: coupling count | J26: Primary | K26: Origins | P26: =IFERROR(__xludf.DUMMYFUNCTION("arrayformula(countif(query('Deprecated Test bed'!D8:H66, ""select E where D='Primary'""), ""Tight Coupling""))"),0.0) -> 0 | Q26: =IFERROR(__xludf.DUMMYFUNCTION("arrayformula(countif(query('Deprecated Test bed'!D8:H66, ""select E where D='Primary'""), ""Medium Coupling""))"),0.0) -> 0 | R26: =IFERROR(__xludf.DUMMYFUNCTION("arrayformula(countif(query('Deprecated Test bed'!D8:H66, ""select E where D='Primary'""), ""Loose Coupling""))"),0.0) -> 0 | S26: =IFERROR(__xludf.DUMMYFUNCTION("arrayformula(countif(query('Deprecated Test bed'!D8:H66, ""select E where D='Primary'""), ""N/A""))"),0.0) -> 0 | T26: =IFERROR(__xludf.DUMMYFUNCTION("arrayformula(countif(query('Deprecated Test bed'!D8:H66, ""select F where D='Primary'""), ""Tight Coupling""))"),0.0) -> 0 | U26: =IFERROR(__xludf.DUMMYFUNCTION("arrayformula(countif(query('Deprecated Test bed'!D8:H66, ""select F where D='Primary'""), ""Medium Coupling""))"),0.0) -> 0 | V26: =IFERROR(__xludf.DUMMYFUNCTION("arrayformula(countif(query('Deprecated Test bed'!D8:H66, ""select F where D='Primary'""), ""Loose Coupling""))"),0.0) -> 0 | W26: =IFERROR(__xludf.DUMMYFUNCTION("arrayformula(countif(query('Deprecated Test bed'!D8:H66, ""select F where D='Primary'""), ""N/A""))"),0.0) -> 0 | X26: =IFERROR(__xludf.DUMMYFUNCTION("arrayformula(countif(query('Deprecated Test bed'!D8:H66, ""select G where D='Primary'""), ""Tight Coupling""))"),0.0) -> 0 | Y26: =IFERROR(__xludf.DUMMYFUNCTION("arrayformula(countif(query('Deprecated Test bed'!D8:H66, ""select G where D='Primary'""), ""Medium Coupling""))"),0.0) -> 0 | Z26: =IFERROR(__xludf.DUMMYFUNCTION("arrayformula(countif(query('Deprecated Test bed'!D8:H66, ""select G where D='Primary'""), ""Loose Coupling""))"),0.0) -> 0 | AA26: =IFERROR(__xludf.DUMMYFUNCTION("arrayformula(countif(query('Deprecated Test bed'!D8:H66, ""select G where D='Primary'""), ""N/A""))"),0.0) -> 0 | AB26: =IFERROR(__xludf.DUMMYFUNCTION("arrayformula(countif(query('Deprecated Test bed'!D8:H66, ""select H where D='Primary'""), ""Tight Coupling""))"),2.0) -> 2 | AC26: =IFERROR(__xludf.DUMMYFUNCTION("arrayformula(countif(query('Deprecated Test bed'!D8:H66, ""select H where D='Primary'""), ""Medium Coupling""))"),2.0) -> 2 | AD26: =IFERROR(__xludf.DUMMYFUNCTION("arrayformula(countif(query('Deprecated Test bed'!D8:H66, ""select H where D='Primary'""), ""Loose Coupling""))"),2.0) -> 2 | AE26: =IFERROR(__xludf.DUMMYFUNCTION("arrayformula(countif(query('Deprecated Test bed'!D8:H66, ""select H where D='Primary'""), ""N/A""))"),2.0) -> 2
B27: Facts | C27: coupling count | E27: coupling count | F27: coupling count | G27: coupling count | K27: Facts | L27: =IFERROR(__xludf.DUMMYFUNCTION("arrayformula(countif(query('Deprecated Test bed'!D8:H66, ""select D where E='Primary'""), ""Tight Coupling""))"),0.0) -> 0 | M27: =IFERROR(__xludf.DUMMYFUNCTION("arrayformula(countif(query('Deprecated Test bed'!D8:H66, ""select D where E='Primary'""), ""Medium Coupling""))"),0.0) -> 0 | N27: =IFERROR(__xludf.DUMMYFUNCTION("arrayformula(countif(query('Deprecated Test bed'!D8:H66, ""select D where E='Primary'""), ""Loose Coupling""))"),0.0) -> 0 | O27: =IFERROR(__xludf.DUMMYFUNCTION("arrayformula(countif(query('Deprecated Test bed'!D8:H66, ""select D where E='Primary'""), ""N/A""))"),1.0) -> 1 | T27: =IFERROR(__xludf.DUMMYFUNCTION("arrayformula(countif(query('Deprecated Test bed'!D8:H66, ""select F where E='Primary'""), ""Tight Coupling""))"),0.0) -> 0 | U27: =IFERROR(__xludf.DUMMYFUNCTION("arrayformula(countif(query('Deprecated Test bed'!D8:H66, ""select F where E='Primary'""), ""Medium Coupling""))"),0.0) -> 0 | V27: =IFERROR(__xludf.DUMMYFUNCTION("arrayformula(countif(query('Deprecated Test bed'!D8:H66, ""select F where E='Primary'""), ""Loose Coupling""))"),0.0) -> 0 | W27: =IFERROR(__xludf.DUMMYFUNCTION("arrayformula(countif(query('Deprecated Test bed'!D8:H66, ""select D where E='Primary'""), ""N/A""))"),1.0) -> 1 | X27: =IFERROR(__xludf.DUMMYFUNCTION("arrayformula(countif(query('Deprecated Test bed'!D8:H66, ""select G where E='Primary'""), ""Tight Coupling""))"),0.0) -> 0 | Y27: =IFERROR(__xludf.DUMMYFUNCTION("arrayformula(countif(query('Deprecated Test bed'!D8:H66, ""select G where E='Primary'""), ""Tight Coupling""))"),0.0) -> 0 | Z27: =IFERROR(__xludf.DUMMYFUNCTION("arrayformula(countif(query('Deprecated Test bed'!D8:H66, ""select G where E='Primary'""), ""Tight Coupling""))"),0.0) -> 0 | AA27: =IFERROR(__xludf.DUMMYFUNCTION("arrayformula(countif(query('Deprecated Test bed'!D8:H66, ""select G where E='Primary'""), ""Tight Coupling""))"),0.0) -> 0 | AB27: =IFERROR(__xludf.DUMMYFUNCTION("arrayformula(countif(query('Deprecated Test bed'!D8:H66, ""select H where E='Primary'""), ""Tight Coupling""))"),2.0) -> 2 | AC27: =IFERROR(__xludf.DUMMYFUNCTION("arrayformula(countif(query('Deprecated Test bed'!D8:H66, ""select H where E='Primary'""), ""Medium Coupling""))"),2.0) -> 2 | AD27: =IFERROR(__xludf.DUMMYFUNCTION("arrayformula(countif(query('Deprecated Test bed'!D8:H66, ""select H where E='Primary'""), ""Loose Coupling""))"),2.0) -> 2 | AE27: =IFERROR(__xludf.DUMMYFUNCTION("arrayformula(countif(query('Deprecated Test bed'!D8:H66, ""select H where E='Primary'""), ""Tight Coupling""))"),2.0) -> 2
B28: Transformations | C28: coupling count | D28: coupling count | F28: coupling count | G28: coupling count | K28: Transformations | L28: =IFERROR(__xludf.DUMMYFUNCTION("arrayformula(countif(query('Deprecated Test bed'!D8:H66, ""select D where F='Primary'""), ""Tight Coupling""))"),8.0) -> 8 | M28: =IFERROR(__xludf.DUMMYFUNCTION("arrayformula(countif(query('Deprecated Test bed'!D8:H66, ""select D where F='Primary'""), ""Medium Coupling""))"),8.0) -> 8 | N28: =IFERROR(__xludf.DUMMYFUNCTION("arrayformula(countif(query('Deprecated Test bed'!D8:H66, ""select D where F='Primary'""), ""Loose Coupling""))"),8.0) -> 8 | O28: =IFERROR(__xludf.DUMMYFUNCTION("arrayformula(countif(query('Deprecated Test bed'!D8:H66, ""select D where F='Primary'""), ""N/A""))"),8.0) -> 8 | P28: =IFERROR(__xludf.DUMMYFUNCTION("arrayformula(countif(query('Deprecated Test bed'!D8:H66, ""select E where F='Primary'""), ""Tight Coupling""))"),8.0) -> 8 | Q28: =IFERROR(__xludf.DUMMYFUNCTION("arrayformula(countif(query('Deprecated Test bed'!D8:H66, ""select E where F='Primary'""), ""Medium Coupling""))"),8.0) -> 8 | R28: =IFERROR(__xludf.DUMMYFUNCTION("arrayformula(countif(query('Deprecated Test bed'!D8:H66, ""select E where F='Primary'""), ""Loose Coupling""))"),8.0) -> 8 | S28: =IFERROR(__xludf.DUMMYFUNCTION("arrayformula(countif(query('Deprecated Test bed'!D8:H66, ""select E where F='Primary'""), ""N/A""))"),7.0) -> 7 | X28: =IFERROR(__xludf.DUMMYFUNCTION("arrayformula(countif(query('Deprecated Test bed'!D8:H66, ""select D where F='Primary'""), ""Tight Coupling""))"),8.0) -> 8 | Y28: =IFERROR(__xludf.DUMMYFUNCTION("arrayformula(countif(query('Deprecated Test bed'!D8:H66, ""select D where F='Primary'""), ""Tight Coupling""))"),8.0) -> 8 | Z28: =IFERROR(__xludf.DUMMYFUNCTION("arrayformula(countif(query('Deprecated Test bed'!D8:H66, ""select D where F='Primary'""), ""Tight Coupling""))"),8.0) -> 8 | AA28: =IFERROR(__xludf.DUMMYFUNCTION("arrayformula(countif(query('Deprecated Test bed'!D8:H66, ""select D where F='Primary'""), ""Tight Coupling""))"),8.0) -> 8 | AB28: =IFERROR(__xludf.DUMMYFUNCTION("arrayformula(countif(query('Deprecated Test bed'!D8:H66, ""select D where F='Primary'""), ""Tight Coupling""))"),8.0) -> 8 | AC28: =IFERROR(__xludf.DUMMYFUNCTION("arrayformula(countif(query('Deprecated Test bed'!D8:H66, ""select D where F='Primary'""), ""Tight Coupling""))"),8.0) -> 8 | AD28: =IFERROR(__xludf.DUMMYFUNCTION("arrayformula(countif(query('Deprecated Test bed'!D8:H66, ""select D where F='Primary'""), ""Tight Coupling""))"),8.0) -> 8 | AE28: =IFERROR(__xludf.DUMMYFUNCTION("arrayformula(countif(query('Deprecated Test bed'!D8:H66, ""select D where F='Primary'""), ""N/A""))"),8.0) -> 8
B29: Experience | C29: coupling count | D29: coupling count | E29: coupling count | G29: coupling count | K29: Experience | L29: =IFERROR(__xludf.DUMMYFUNCTION("arrayformula(countif(query('Deprecated Test bed'!D8:H66, ""select D where G='Primary'""), ""Tight Coupling""))"),0.0) -> 0 | M29: =IFERROR(__xludf.DUMMYFUNCTION("arrayformula(countif(query('Deprecated Test bed'!D8:H66, ""select D where G='Primary'""), ""Medium Coupling""))"),0.0) -> 0 | N29: =IFERROR(__xludf.DUMMYFUNCTION("arrayformula(countif(query('Deprecated Test bed'!D8:H66, ""select D where G='Primary'""), ""Loose Coupling""))"),0.0) -> 0 | O29: =IFERROR(__xludf.DUMMYFUNCTION("arrayformula(countif(query('Deprecated Test bed'!D8:H66, ""select D where G='Primary'""), ""N/A""))"),0.0) -> 0 | P29: =IFERROR(__xludf.DUMMYFUNCTION("arrayformula(countif(query('Deprecated Test bed'!D8:H66, ""select E where G='Primary'""), ""Tight Coupling""))"),0.0) -> 0 | Q29: =IFERROR(__xludf.DUMMYFUNCTION("arrayformula(countif(query('Deprecated Test bed'!D8:H66, ""select E where G='Primary'""), ""Medium Coupling""))"),0.0) -> 0 | R29: =IFERROR(__xludf.DUMMYFUNCTION("arrayformula(countif(query('Deprecated Test bed'!D8:H66, ""select E where G='Primary'""), ""Loose Coupling""))"),0.0) -> 0 | S29: =IFERROR(__xludf.DUMMYFUNCTION("arrayformula(countif(query('Deprecated Test bed'!D8:H66, ""select E where G='Primary'""), ""N/A""))"),0.0) -> 0 | T29: =IFERROR(__xludf.DUMMYFUNCTION("arrayformula(countif(query('Deprecated Test bed'!D8:H66, ""select F where G='Primary'""), ""Tight Coupling""))"),0.0) -> 0 | U29: =IFERROR(__xludf.DUMMYFUNCTION("arrayformula(countif(query('Deprecated Test bed'!D8:H66, ""select F where G='Primary'""), ""Medium Coupling""))"),0.0) -> 0 | V29: =IFERROR(__xludf.DUMMYFUNCTION("arrayformula(countif(query('Deprecated Test bed'!D8:H66, ""select F where G='Primary'""), ""Loose Coupling""))"),0.0) -> 0 | W29: =IFERROR(__xludf.DUMMYFUNCTION("arrayformula(countif(query('Deprecated Test bed'!D8:H66, ""select F where G='Primary'""), ""N/A""))"),0.0) -> 0 | AB29: =IFERROR(__xludf.DUMMYFUNCTION("arrayformula(countif(query('Deprecated Test bed'!D8:H66, ""select H where G='Primary'""), ""Tight Coupling""))"),0.0) -> 0 | AC29: =IFERROR(__xludf.DUMMYFUNCTION("arrayformula(countif(query('Deprecated Test bed'!D8:H66, ""select F where G='Primary'""), ""Medium Coupling""))"),0.0) -> 0 | AD29: =IFERROR(__xludf.DUMMYFUNCTION("arrayformula(countif(query('Deprecated Test bed'!D8:H66, ""select F where G='Primary'""), ""Loose Coupling""))"),0.0) -> 0 | AE29: =IFERROR(__xludf.DUMMYFUNCTION("arrayformula(countif(query('Deprecated Test bed'!D8:H66, ""select F where G='Primary'""), ""N/A""))"),0.0) -> 0
